Workbook

Sheet 1 a 12
A1: LOGO | J1: Ordem de Serviço
J2: Prioridade:
J3: URGENTE | M3: 24 horas
J4: ALTA | M4: 3 dias
J5: MÉDIA | M5: 7 dias
J6: BAIXA | M6: 15 dias
A7: UNIDADE: UFSCar Campus São Carlos | J7: CONTRATO: 023/2022 | O7: SOLICITAÇÃO
A8: Descrição serviço: ROTINAS DE MANUTENÇÃO PREDIAL NO CAMPUS SÃO CARLOS, REFERENTE AO PERIDO DE 01/06/2024 a 12/06/2024 | J8: Solicitante: Prefeitura Universitária do Campus São Carlos
J9: Ambiente: Campus São Carlos
J10: Prazo de execução: Continuado
J11: Prazo de início: 13/06/2022
J12: Data Orçamento: Jun/23
J13: Mês de referência: Maio/2023 (data da proposta)
A14: ITEM | B14: TIPO | C14: CÓDIGO | D14: BANCO | E14: DESCRIÇÃO DAS ETAPAS | F14: UNID. | G14: QUANT. | H14: PREÇO | M14: TOTAL DA ETAPA | N14: % | O14: ORÇAMENTO
H15: UNITÁRIO SEM BDI | I15: BDI (22,32%) | J15: UNITÁRIO COM BDI | K15: DESCONTO (0,03%) | L15: UNITÁRIO C/ BDI e DESCONTO
A16: 1 | E16: EQUIPE DE PRESTAÇÃO DE SERVIÇOS ROTINEIROS DE MANUTENÇÃO PREDIAL | M16: =SUM(M17:M28) -> 38868.482 | N16: =SUM(N17:N28) -> 1
A17: 1.1 | B17: Composição | C17: 90776 | D17: SINAPI | E17: ENCARREGADO GERAL COM ENCARGOS COMPLEMENTARES | F17: h | G17: 85 | H17: 47.89 | I17: =H17*0.2232 -> 10.689048 | J17: =H17+I17 -> 58.579048 | K17: =J17*(0.03%) -> 0.017573714 | L17: =J17-K17 -> 58.561474 | M17: =L17*G17 -> 4977.7253 | N17: =M17/M$16 -> 0.12806585
A18: 1.2 | B18: Composição | C18: 88267 | D18: SINAPI | E18: ENCANADOR OU BOMBEIRO HIDRÁULICO COM ENCARGOS COMPLEMENTARES | F18: h | G18: 85 | H18: 36.11 | I18: =H18*0.2232 -> 8.059752 | J18: =H18+I18 -> 44.169752 | K18: =J18*(0.03%) -> 0.013250926 | L18: =J18-K18 -> 44.156501 | M18: =L18*G18 -> 3753.3026 | N18: =M18/M$16 -> 0.096564167
A19: 1.3 | B19: Composição | C19: 88267 | D19: SINAPI | E19: ENCANADOR OU BOMBEIRO HIDRÁULICO COM ENCARGOS COMPLEMENTARES | F19: h | G19: 80 | H19: 36.11 | I19: =H19*0.2232 -> 8.059752 | J19: =H19+I19 -> 44.169752 | K19: =J19*(0.03%) -> 0.013250926 | L19: =J19-K19 -> 44.156501 | M19: =L19*G19 -> 3532.5201 | N19: =M19/M$16 -> 0.090883922
A20: 1.4 | B20: Composição | C20: 88248 | D20: SINAPI | E20: AUXILIAR DE ENCANADOR OU BOMBEIRO HIDRÁULICO COM ENCARGOS COMPLEMENTARES | F20: h | G20: 80 | H20: 29.77 | I20: =H20*0.2232 -> 6.644664 | J20: =H20+I20 -> 36.414664 | K20: =J20*(0.03%) -> 0.010924399 | L20: =J20-K20 -> 36.40374 | M20: =L20*G20 -> 2912.2992 | N20: =M20/M$16 -> 0.074927011
A21: 1.5 | B21: Composição | C21: 88248 | D21: SINAPI | E21: AUXILIAR DE ENCANADOR OU BOMBEIRO HIDRÁULICO COM ENCARGOS COMPLEMENTARES | F21: h | G21: 80 | H21: 29.77 | I21: =H21*0.2232 -> 6.644664 | J21: =H21+I21 -> 36.414664 | K21: =J21*(0.03%) -> 0.010924399 | L21: =J21-K21 -> 36.40374 | M21: =L21*G21 -> 2912.2992 | N21: =M21/M$16 -> 0.074927011
A22: 1.6 | B22: Composição | C22: 88309 | D22: SINAPI | E22: PEDREIRO COM ENCARGOS COMPLEMENTARES | F22: h | G22: 80 | H22: 32.57 | I22: =H22*0.2232 -> 7.269624 | J22: =H22+I22 -> 39.839624 | K22: =J22*(0.03%) -> 0.011951887 | L22: =J22-K22 -> 39.827672 | M22: =L22*G22 -> 3186.2138 | N22: =M22/M$16 -> 0.081974227
A23: 1.7 | B23: Composição | C23: 88309 | D23: SINAPI | E23: PEDREIRO COM ENCARGOS COMPLEMENTARES | F23: h | G23: 80 | H23: 32.57 | I23: =H23*0.2232 -> 7.269624 | J23: =H23+I23 -> 39.839624 | K23: =J23*(0.03%) -> 0.011951887 | L23: =J23-K23 -> 39.827672 | M23: =L23*G23 -> 3186.2138 | N23: =M23/M$16 -> 0.081974227
A24: 1.8 | B24: Composição | C24: 88242 | D24: SINAPI | E24: AJUDANTE DE PEDREIRO COM ENCARGOS COMPLEMENTARES | F24: h | G24: 80 | H24: 30.38 | I24: =H24*0.2232 -> 6.780816 | J24: =H24+I24 -> 37.160816 | K24: =J24*(0.03%) -> 0.011148245 | L24: =J24-K24 -> 37.149668 | M24: =L24*G24 -> 2971.9734 | N24: =M24/M$16 -> 0.076462297
A25: 1.9 | B25: Composição | C25: 88242 | D25: SINAPI | E25: AJUDANTE DE PEDREIRO COM ENCARGOS COMPLEMENTARES | F25: h | G25: 80 | H25: 30.38 | I25: =H25*0.2232 -> 6.780816 | J25: =H25+I25 -> 37.160816 | K25: =J25*(0.03%) -> 0.011148245 | L25: =J25-K25 -> 37.149668 | M25: =L25*G25 -> 2971.9734 | N25: =M25/M$16 -> 0.076462297
A26: 1.10 | B26: Composição | C26: 88242 | D26: SINAPI | E26: AJUDANTE DE PEDREIRO COM ENCARGOS COMPLEMENTARES | F26: h | G26: 80 | H26: 30.38 | I26: =H26*0.2232 -> 6.780816 | J26: =H26+I26 -> 37.160816 | K26: =J26*(0.03%) -> 0.011148245 | L26: =J26-K26 -> 37.149668 | M26: =L26*G26 -> 2971.9734 | N26: =M26/M$16 -> 0.076462297
A27: 1.11 | B27: Composição | C27: 88241 | D27: SINAPI | E27: AJUDANTE DE OPERAÇÃO EM GERAL COM ENCARGOS COMPLEMENTARES | F27: h | G27: 80 | H27: 28.07 | I27: =H27*0.2232 -> 6.265224 | J27: =H27+I27 -> 34.335224 | K27: =J27*(0.03%) -> 0.010300567 | L27: =J27-K27 -> 34.324923 | M27: =L27*G27 -> 2745.9939 | N27: =M27/M$16 -> 0.070648344
A28: 1.12 | B28: Composição | C28: 88241 | D28: SINAPI | E28: AJUDANTE DE OPERAÇÃO EM GERAL COM ENCARGOS COMPLEMENTARES | F28: h | G28: 80 | H28: 28.07 | I28: =H28*0.2232 -> 6.265224 | J28: =H28+I28 -> 34.335224 | K28: =J28*(0.03%) -> 0.010300567 | L28: =J28-K28 -> 34.324923 | M28: =L28*G28 -> 2745.9939 | N28: =M28/M$16 -> 0.070648344
A29: ITEM | B29: TIPO | C29: CÓDIGO | D29: BANCO | E29: DESCRIÇÃO DAS ETAPAS | F29: UNID. | G29: QUANT. | H29: PREÇO | M29: TOTAL DA ETAPA | N29: %
H30: UNITÁRIO SEM BDI | I30: BDI (15,32%) | J30: UNITÁRIO COM BDI | K30: DESCONTO (0,03%) | L30: UNITÁRIO C/ BDI e DESCONTO
A31: 2 | B31: MATERIAIS NECESSÁRIOS PARA O DESEMPENHO DAS ROTINAS | M31: =SUM(M32:M37) -> 0
A38: ITEM | B38: TIPO | C38: CÓDIGO | D38: BANCO | E38: DESCRIÇÃO DAS ETAPAS | F38: UNID. | G38: QUANT. | H38: PREÇO | M38: TOTAL DA ETAPA | N38: %
H39: UNITÁRIO SEM BDI | I39: BDI (22,32%) | J39: UNITÁRIO COM BDI | K39: ESCONTO (0,03%) | L39: UNITÁRIO C/ BDI e DESCONTO
A40: 3 | B40: SERVIÇOS / EQUIPAMENTOS ADICIONAIS NECESSÁRIOS DURANTE AS ROTINAS | M40: =SUM(M41:M43) -> 6158.1872
A41: 3.1 | B41: Composição | C41: 88309 | D41: SINAPI | E41: PEDREIRO COM ENCARGOS COMPLEMENTARES | F41: h | G41: 80 | H41: 32.57 | I41: =H41*0.2232 -> 7.269624 | J41: =H41+I41 -> 39.839624 | K41: =J41*(0.03%) -> 0.011951887 | L41: =J41-K41 -> 39.827672 | M41: =L41*G41 -> 3186.2138 | N41: =M41/M$16 -> 0.081974227
A42: 3.2 | B42: Composição | C42: 88242 | D42: SINAPI | E42: AJUDANTE DE PEDREIRO COM ENCARGOS COMPLEMENTARES | F42: h | G42: 80 | H42: 30.38 | I42: =H42*0.2232 -> 6.780816 | J42: =H42+I42 -> 37.160816 | K42: =J42*(0.03%) -> 0.011148245 | L42: =J42-K42 -> 37.149668 | M42: =L42*G42 -> 2971.9734 | N42: =M42/M$16 -> 0.076462297
A43: 3.3 | B43: Composição | C43: 88310 | D43: SINAPI | E43: PINTOR COM ENCARGOS COMPLEMENTARES | F43: h | G43: 0 | H43: 35.88 | I43: =H43*0.2232 -> 8.008416 | J43: =H43+I43 -> 43.888416 | K43: =J43*(0.03%) -> 0.013166525 | L43: =J43-K43 -> 43.875249 | M43: =L43*G43 -> 0 | N43: =M43/M$16 -> 0
H45: TOTAL DO SERVIÇO - R$ | J45: =M16+M31+M40 -> 45026.669
A46: Observações: 1) As composições de custos apresentadas nesta planilha orçamentária englobam em seu valor toda a mão de obra, materiais, ferramentas, equipamentos e demais itens necessários à sua perfeita e completa execução. 2) Preços das composições e insumos do SINAPI São Paulo (mês 05/2023) e/ou demais preços do mercado vigentes na mesma data. 3) A identificação de materiais ou equipamentos por determinada marca implica apenas na caracterização de uma analogia ou similaridade, não tendo caráter vinculante e sim, meramente indicativo. 4) O BDI e o desconto adotados são os acordados no respectivo contrato, bem como a modalidade de impostos desonerados ou padrão, considerando o ISS da Prefeitura local do serviço.
A54: APROVAÇÃO DO ORÇAMENTO | G54: Ordem Serviço Eletrônica | O54: APROVAÇÃO ORÇAMENTO
...

Sheet 13 a 30
A1: LOGO | J1: Ordem de Serviço
J2: Prioridade:
J3: URGENTE | M3: 24 horas
J4: ALTA | M4: 3 dias
J5: MÉDIA | M5: 7 dias
J6: BAIXA | M6: 15 dias
A7: UNIDADE: UFSCar Campus São Carlos | J7: CONTRATO: 023/2022 | O7: SOLICITAÇÃO
A8: Descrição serviço: ROTINAS DE MANUTENÇÃO PREDIAL NO CAMPUS SÃO CARLOS, REFERENTE AO PERIDO DE 13/06/2024 a 30/06/2024 | J8: Solicitante: Prefeitura Universitária do Campus São Carlos
J9: Ambiente: Campus São Carlos
J10: Prazo de execução: Continuado
J11: Prazo de início: 13/06/2022
J12: Data Orçamento: Jun/22
J13: Mês de referência: Maio/2024 (data da proposta)
A14: ITEM | B14: TIPO | C14: CÓDIGO | D14: BANCO | E14: DESCRIÇÃO DAS ETAPAS | F14: UNID. | G14: QUANT. | H14: PREÇO | M14: TOTAL DA ETAPA | N14: % | O14: ORÇAMENTO
H15: UNITÁRIO SEM BDI | I15: BDI (22,32%) | J15: UNITÁRIO COM BDI | K15: DESCONTO (0,03%) | L15: UNITÁRIO C/ BDI e DESCONTO
A16: 1 | E16: EQUIPE DE PRESTAÇÃO DE SERVIÇOS ROTINEIROS DE MANUTENÇÃO PREDIAL | M16: =SUM(M17:M28) -> 61802.96 | N16: =SUM(N17:N28) -> 1
A17: 1.1 | B17: Composição | C17: 90776 | D17: SINAPI | E17: ENCARREGADO GERAL COM ENCARGOS COMPLEMENTARES | F17: h | G17: =117.5+30 -> 147.5 | H17: 47.89 | I17: =H17*0.2232 -> 10.689048 | J17: =H17+I17 -> 58.579048 | K17: =J17*(0.03%) -> 0.017573714 | L17: =J17-K17 -> 58.561474 | M17: =L17*G17 -> 8637.8175 | N17: =M17/M$16 -> 0.13976381
A18: 1.2 | B18: Composição | C18: 88267 | D18: SINAPI | E18: ENCANADOR OU BOMBEIRO HIDRÁULICO COM ENCARGOS COMPLEMENTARES | F18: h | G18: =114.5+30 -> 144.5 | H18: 36.11 | I18: =H18*0.2232 -> 8.059752 | J18: =H18+I18 -> 44.169752 | K18: =J18*(0.03%) -> 0.013250926 | L18: =J18-K18 -> 44.156501 | M18: =L18*G18 -> 6380.6144 | N18: =M18/M$16 -> 0.10324124
A19: 1.3 | B19: Composição | C19: 88267 | D19: SINAPI | E19: ENCANADOR OU BOMBEIRO HIDRÁULICO COM ENCARGOS COMPLEMENTARES | F19: h | G19: =100+30 -> 130 | H19: 36.11 | I19: =H19*0.2232 -> 8.059752 | J19: =H19+I19 -> 44.169752 | K19: =J19*(0.03%) -> 0.013250926 | L19: =J19-K19 -> 44.156501 | M19: =L19*G19 -> 5740.3451 | N19: =M19/M$16 -> 0.092881395
A20: 1.4 | B20: Composição | C20: 88248 | D20: SINAPI | E20: AUXILIAR DE ENCANADOR OU BOMBEIRO HIDRÁULICO COM ENCARGOS COMPLEMENTARES | F20: h | G20: =110+45 -> 155 | H20: 29.77 | I20: =H20*0.2232 -> 6.644664 | J20: =H20+I20 -> 36.414664 | K20: =J20*(0.03%) -> 0.010924399 | L20: =J20-K20 -> 36.40374 | M20: =L20*G20 -> 5642.5796 | N20: =M20/M$16 -> 0.091299505
A21: 1.5 | B21: Composição | C21: 88248 | D21: SINAPI | E21: AUXILIAR DE ENCANADOR OU BOMBEIRO HIDRÁULICO COM ENCARGOS COMPLEMENTARES | F21: h | G21: =100+45 -> 145 | H21: 29.77 | I21: =H21*0.2232 -> 6.644664 | J21: =H21+I21 -> 36.414664 | K21: =J21*(0.03%) -> 0.010924399 | L21: =J21-K21 -> 36.40374 | M21: =L21*G21 -> 5278.5422 | N21: =M21/M$16 -> 0.085409214
A22: 1.6 | B22: Composição | C22: 88309 | D22: SINAPI | E22: PEDREIRO COM ENCARGOS COMPLEMENTARES | F22: h | G22: =100+45 -> 145 | H22: 32.57 | I22: =H22*0.2232 -> 7.269624 | J22: =H22+I22 -> 39.839624 | K22: =J22*(0.03%) -> 0.011951887 | L22: =J22-K22 -> 39.827672 | M22: =L22*G22 -> 5775.0125 | N22: =M22/M$16 -> 0.093442328
A23: 1.7 | B23: Composição | C23: 88309 | D23: SINAPI | E23: PEDREIRO COM ENCARGOS COMPLEMENTARES | F23: h | G23: =100+45 -> 145 | H23: 32.57 | I23: =H23*0.2232 -> 7.269624 | J23: =H23+I23 -> 39.839624 | K23: =J23*(0.03%) -> 0.011951887 | L23: =J23-K23 -> 39.827672 | M23: =L23*G23 -> 5775.0125 | N23: =M23/M$16 -> 0.093442328
A24: 1.8 | B24: Composição | C24: 88242 | D24: SINAPI | E24: AJUDANTE DE PEDREIRO COM ENCARGOS COMPLEMENTARES | F24: h | G24: =100+30 -> 130 | H24: 30.38 | I24: =H24*0.2232 -> 6.780816 | J24: =H24+I24 -> 37.160816 | K24: =J24*(0.03%) -> 0.011148245 | L24: =J24-K24 -> 37.149668 | M24: =L24*G24 -> 4829.4568 | N24: =M24/M$16 -> 0.078142807
A25: 1.9 | B25: Composição | C25: 88242 | D25: SINAPI | E25: AJUDANTE DE PEDREIRO COM ENCARGOS COMPLEMENTARES | F25: h | G25: =100+30 -> 130 | H25: 30.38 | I25: =H25*0.2232 -> 6.780816 | J25: =H25+I25 -> 37.160816 | K25: =J25*(0.03%) -> 0.011148245 | L25: =J25-K25 -> 37.149668 | M25: =L25*G25 -> 4829.4568 | N25: =M25/M$16 -> 0.078142807
A26: 1.10 | B26: Composição | C26: 88242 | D26: SINAPI | E26: AJUDANTE DE PEDREIRO COM ENCARGOS COMPLEMENTARES | F26: h | G26: =100+30 -> 130 | H26: 30.38 | I26: =H26*0.2232 -> 6.780816 | J26: =H26+I26 -> 37.160816 | K26: =J26*(0.03%) -> 0.011148245 | L26: =J26-K26 -> 37.149668 | M26: =L26*G26 -> 4829.4568 | N26: =M26/M$16 -> 0.078142807
A27: 1.11 | B27: Composição | C27: 88241 | D27: SINAPI | E27: AJUDANTE DE OPERAÇÃO EM GERAL COM ENCARGOS COMPLEMENTARES | F27: h | G27: 91 | H27: 28.07 | I27: =H27*0.2232 -> 6.265224 | J27: =H27+I27 -> 34.335224 | K27: =J27*(0.03%) -> 0.010300567 | L27: =J27-K27 -> 34.324923 | M27: =L27*G27 -> 3123.568 | N27: =M27/M$16 -> 0.050540751
A28: 1.12 | B28: Composição | C28: 88241 | D28: SINAPI | E28: AJUDANTE DE OPERAÇÃO EM GERAL COM ENCARGOS COMPLEMENTARES | F28: h | G28: 28 | H28: 28.07 | I28: =H28*0.2232 -> 6.265224 | J28: =H28+I28 -> 34.335224 | K28: =J28*(0.03%) -> 0.010300567 | L28: =J28-K28 -> 34.324923 | M28: =L28*G28 -> 961.09786 | N28: =M28/M$16 -> 0.015551
A29: ITEM | B29: TIPO | C29: CÓDIGO | D29: BANCO | E29: DESCRIÇÃO DAS ETAPAS | F29: UNID. | G29: QUANT. | H29: PREÇO | M29: TOTAL DA ETAPA | N29: %
H30: UNITÁRIO SEM BDI | I30: BDI (15,32%) | J30: UNITÁRIO COM BDI | K30: DESCONTO (0,03%) | L30: UNITÁRIO C/ BDI e DESCONTO
A31: 2 | B31: MATERIAIS NECESSÁRIOS PARA O DESEMPENHO DAS ROTINAS | M31: =SUM(M32:M65) -> 14014.533
A32: 2.1 | B32: Insumos | C32: 43132 | D32: SINAPI | E32: ARAME RECOZIDO 16 BWG, D = 1,65 MM (0,016 KG/M) OU 18 BWG, D = 1,25 MM (0,01 KG/M) | F32: kg | G32: 6 | H32: 16.5 | I32: =H32*0.1532 -> 2.5278 | J32: =H32+I32 -> 19.0278 | K32: =J32*(0.03%) -> 0.00570834 | L32: =J32-K32 -> 19.022092 | M32: =L32*G32 -> 114.13255 | N32: =M32/M31 -> 0.0081438711
A33: 2.2 | B33: Insumos | C33: 1379 | D33: SINAPI | E33: CIMENTO PORTLAND COMPOSTO CP II-32 | F33: UNID. | G33: 2000 | H33: 0.6 | I33: =H33*0.1532 -> 0.09192 | J33: =H33+I33 -> 0.69192 | K33: =J33*(0.03%) -> 0.000207576 | L33: =J33-K33 -> 0.69171242 | M33: =L33*G33 -> 1383.4248 | N33: =M33/M32 -> 12.121212
A34: 2.3 | B34: Insumos | C34: 6754 | D34: ORSE | E34: Adesivo para tubo Aquatherm/CPVC | F34: KG | G34: 1.7 | H34: 318.53 | I34: =H34*0.1532 -> 48.798796 | J34: =H34+I34 -> 367.3288 | K34: =J34*(0.03%) -> 0.11019864 | L34: =J34-K34 -> 367.2186 | M34: =L34*G34 -> 624.27162 | N34: =M34/M33 -> 0.45125083
A35: 2.4 | B35: Insumos | C35: 34357 | D35: SINAPI | E35: REJUNTE CIMENTICIO, QUALQUER COR | F35: KG | G35: 6 | H35: 4.4 | I35: =H35*0.1532 -> 0.67408 | J35: =H35+I35 -> 5.07408 | K35: =J35*(0.03%) -> 0.001522224 | L35: =J35-K35 -> 5.0725578 | M35: =L35*G35 -> 30.435347 | N35: =M35/M34 -> 0.048753373
A36: 2.5 | B36: Insumos | C36: 7258 | D36: SINAPI | E36: TIJOLO CERAMICO MACICO COMUM DE *5 X 10 X 20* CM (L X A X C) | F36: UNID. | G36: 700 | H36: 0.67 | I36: =H36*0.1532 -> 0.102644 | J36: =H36+I36 -> 0.772644 | K36: =J36*(0.03%) -> 0.0002317932 | L36: =J36-K36 -> 0.77241221 | M36: =L36*G36 -> 540.68854 | N36: =M36/M35 -> 17.765152
A37: 2.6 | B37: Insumos | C37: 7271 | D37: SINAPI | E37: BLOCO CERAMICO / TIJOLO VAZADO PARA ALVENARIA DE VEDACAO, 8 FUROS NA HORIZONTAL DE 9 X 19 X 19 CM (L X A X C) | F37: UNID. | G37: 500 | H37: 0.78 | I37: =H37*0.1532 -> 0.119496 | J37: =H37+I37 -> 0.899496 | K37: =J37*(0.03%) -> 0.0002698488 | L37: =J37-K37 -> 0.89922615 | M37: =L37*G37 -> 449.61308 | N37: =M37/M36 -> 0.8315565
A38: 2.7 | B38: Insumos | C38: 366 | D38: SINAPI | E38: AREIA FINA - POSTO JAZIDA/FORNECEDOR (RETIRADO NA JAZIDA, SEM TRANSPORTE) | F38: m3 | G38: 3 | H38: 65 | I38: =H38*0.1532 -> 9.958 | J38: =H38+I38 -> 74.958 | K38: =J38*(0.03%) -> 0.0224874 | L38: =J38-K38 -> 74.935513 | M38: =L38*G38 -> 224.80654 | N38: =M38/M37 -> 0.5
A39: 2.8 | B39: Insumos | C39: 367 | D39: SINAPI | E39: AREIA GROSSA - POSTO JAZIDA/FORNECEDOR (RETIRADO NA JAZIDA, SEM TRANSPORTE) | F39: m3 | G39: 5 | H39: 65.84 | I39: =H39*0.1532 -> 10.086688 | J39: =H39+I39 -> 75.926688 | K39: =J39*(0.03%) -> 0.022778006 | L39: =J39-K39 -> 75.90391 | M39: =L39*G39 -> 379.51955 | N39: =M39/M38 -> 1.6882051
A40: 2.9 | B40: Insumos | C40: 4720 | D40: SINAPI | E40: PEDRA BRITADA N. 0, OU PEDRISCO (4,8 A 9,5 MM) POSTO PEDREIRA/FORNECEDOR, SEM FRETE | F40: m3 | G40: 5 | H40: 80.39 | I40: =H40*0.1532 -> 12.315748 | J40: =H40+I40 -> 92.705748 | K40: =J40*(0.03%) -> 0.027811724 | L40: =J40-K40 -> 92.677936 | M40: =L40*G40 -> 463.38968 | N40: =M40/M39 -> 1.2209903
...

Sheet Planilha3
I1: 1 a 12 | K1: 13 a 30 | O1: REV | P1: Red greve - comp
B2: ='1 a 12'!E17 -> ENCARREGADO GERAL COM ENCARGOS COMPLEMENTARES | I2: ='1 a 12'!G17 -> 85 | K2: ='13 a 30'!G17 -> 147.5 | M2: =I2+K2 -> 232.5 | O2: =M2 -> 232.5
B3: ='1 a 12'!E18 -> ENCANADOR OU BOMBEIRO HIDRÁULICO COM ENCARGOS COMPLEMENTARES | I3: ='1 a 12'!G18 -> 85 | K3: ='13 a 30'!G18 -> 144.5 | M3: =I3+K3 -> 229.5 | O3: =M3 -> 229.5
B4: ='1 a 12'!E19 -> ENCANADOR OU BOMBEIRO HIDRÁULICO COM ENCARGOS COMPLEMENTARES | I4: ='1 a 12'!G19 -> 80 | K4: ='13 a 30'!G19 -> 130 | M4: =I4+K4 -> 210 | O4: =M4 -> 210
B5: ='1 a 12'!E20 -> AUXILIAR DE ENCANADOR OU BOMBEIRO HIDRÁULICO COM ENCARGOS COMPLEMENTARES | I5: ='1 a 12'!G20 -> 80 | K5: ='13 a 30'!G20 -> 155 | M5: =I5+K5 -> 235 | O5: =M5 -> 235
B6: ='1 a 12'!E21 -> AUXILIAR DE ENCANADOR OU BOMBEIRO HIDRÁULICO COM ENCARGOS COMPLEMENTARES | I6: ='1 a 12'!G21 -> 80 | K6: ='13 a 30'!G21 -> 145 | M6: =I6+K6 -> 225 | O6: =M6 -> 225
B7: ='1 a 12'!E22 -> PEDREIRO COM ENCARGOS COMPLEMENTARES | I7: ='1 a 12'!G22 -> 80 | K7: ='13 a 30'!G22 -> 145 | M7: =I7+K7 -> 225 | O7: =M7 -> 225
B8: ='1 a 12'!E23 -> PEDREIRO COM ENCARGOS COMPLEMENTARES | I8: ='1 a 12'!G23 -> 80 | K8: ='13 a 30'!G23 -> 145 | M8: =I8+K8 -> 225 | O8: =M8 -> 225
B9: ='1 a 12'!E24 -> AJUDANTE DE PEDREIRO COM ENCARGOS COMPLEMENTARES | I9: ='1 a 12'!G24 -> 80 | K9: ='13 a 30'!G24 -> 130 | M9: =I9+K9 -> 210 | O9: =M9 -> 210
B10: ='1 a 12'!E25 -> AJUDANTE DE PEDREIRO COM ENCARGOS COMPLEMENTARES | I10: ='1 a 12'!G25 -> 80 | K10: ='13 a 30'!G25 -> 130 | M10: =I10+K10 -> 210 | O10: =M10 -> 210
B11: ='1 a 12'!E26 -> AJUDANTE DE PEDREIRO COM ENCARGOS COMPLEMENTARES | I11: ='1 a 12'!G26 -> 80 | K11: ='13 a 30'!G26 -> 130 | M11: =I11+K11 -> 210 | O11: =M11 -> 210
B12: ='1 a 12'!E27 -> AJUDANTE DE OPERAÇÃO EM GERAL COM ENCARGOS COMPLEMENTARES | I12: ='1 a 12'!G27 -> 80 | K12: ='13 a 30'!G27 -> 91 | M12: =I12+K12 -> 171 | O12: =M12 -> 171
B13: ='1 a 12'!E28 -> AJUDANTE DE OPERAÇÃO EM GERAL COM ENCARGOS COMPLEMENTARES | I13: ='1 a 12'!G28 -> 80 | K13: ='13 a 30'!G28 -> 28 | M13: =I13+K13 -> 108 | N13: Errado | O13: 108
B16: ='1 a 12'!E41 -> PEDREIRO COM ENCARGOS COMPLEMENTARES | I16: ='1 a 12'!G41 -> 80 | K16: ='13 a 30'!G69 -> 100 | M16: =K16+I16 -> 180 | O16: =M16 -> 180
B17: ='1 a 12'!E42 -> AJUDANTE DE PEDREIRO COM ENCARGOS COMPLEMENTARES | I17: ='1 a 12'!G42 -> 80 | K17: ='13 a 30'!G71 -> 100 | M17: =K17+I17 -> 180 | O17: =M17 -> 180
B18: ='1 a 12'!E43 -> PINTOR COM ENCARGOS COMPLEMENTARES | I18: ='1 a 12'!G43 -> 0 | K18: ='13 a 30'!G72 -> 105 | M18: =K18+I18 -> 105 | O18: =M18 -> 105

Sheet Planilha1
B3: ITEM 02 – AT. 07
B4: QTD
B5: DESCRIÇÃO O ITEM
B6: R$
B7: 1
B8: CHAVE DE STORZ P/ HIDRANTE
B9: 20
B10: 40
B11: 7
B12: EXTINTOR DE PÓ BC 4KG (RECARGA)
B13: 45
B14: 315
B15: 7
B16: EXTINTOR DE AGUA PRESSURIZADA 10L (RECARGA)
B17: 45
B18: 315
B19: 7
B20: MANGUEIRA TIPO 2 – 30m -1.¹/2 (NOVO)
B21: 690
B22: 4830
B23: 7
B24: ESGUICHO REGULAVEL
